<mujoco model="arm3d">
	<compiler coordinate="local" angle="radian" inertiafromgeom="true"/>
	<option timestep="0.01" integrator="Euler" gravity="0 0 0" iterations="20"/>
	<default >
		<joint limited="true" armature="0.04" damping="1"/>
		<geom contype="0" condim="1" margin="0.002" conaffinity="0" friction="0.8 0.1 0.1" density="300"/>
	</default>
	<worldbody >
		<light diffuse=".5 .5 .5" pos="0 0 3" dir="0 0 -1"/>
		<geom contype="1" name="table" size="1 1 0.1" type="plane" pos="0 0.5 -0.325" conaffinity="1"/>
		<body name="r_shoulder_pan_link" pos="0 -0.6 0">
			<geom rgba="0.6 0.6 0.6 1" name="e1" size="0.05" type="sphere" pos="-0.06 0.05 0.2"/>
			<geom rgba="0.6 0.6 0.6 1" name="e2" size="0.05" type="sphere" pos=" 0.06 0.05 0.2"/>
			<geom rgba="0.1 0.1 0.1 1" name="e1p" size="0.03" type="sphere" pos="-0.06 0.09 0.2"/>
			<geom rgba="0.1 0.1 0.1 1" name="e2p" size="0.03" type="sphere" pos=" 0.06 0.09 0.2"/>
			<geom name="sp" size="0.1" type="capsule" fromto="0 0 -0.4 0 0 0.2"/>
			<joint name="r_shoulder_pan_joint" type="hinge" pos="0 0 0" damping="1.0" range="-2.2854 1.714602" axis="0 0 1"/>
			<body name="r_shoulder_lift_link" pos="0.1 0 0">
				<geom name="sl" size="0.1" type="capsule" fromto="0 -0.1 0 0 0.1 0"/>
				<joint name="r_shoulder_lift_joint" type="hinge" pos="0 0 0" damping="1.0" range="-0.5236 1.3963" axis="0 1 0"/>
				<body name="r_upper_arm_roll_link" pos="0 0 0">
					<geom name="uar" size="0.02" type="capsule" fromto="-0.1 0 0 0.1 0 0"/>
					<joint name="r_upper_arm_roll_joint" type="hinge" pos="0 0 0" damping="0.1" range="-1.5 1.7" axis="1 0 0"/>
					<body name="r_upper_arm_link" pos="0 0 0">
						<geom name="ua" size="0.06" type="capsule" fromto="0 0 0 0.4 0 0"/>
						<body name="r_elbow_flex_link" pos="0.4 0 0">
							<geom name="ef" size="0.06" type="capsule" fromto="0 -0.02 0 0.0 0.02 0"/>
							<joint name="r_elbow_flex_joint" type="hinge" pos="0 0 0" damping="0.1" range="-2.3213 0" axis="0 1 0"/>
							<body name="r_forearm_roll_link" pos="0 0 0">
								<geom name="fr" size="0.02" type="capsule" fromto="-0.1 0 0 0.1 0 0"/>
								<joint limited="true" name="r_forearm_roll_joint" type="hinge" pos="0 0 0" damping=".1" range="-1.5 1.5" axis="1 0 0"/>
								<body name="r_forearm_link" pos="0 0 0">
									<geom name="fa" size="0.05" type="capsule" fromto="0 0 0 0.291 0 0"/>
									<body name="r_wrist_flex_link" pos="0.321 0 0">
										<geom name="wf" size="0.01" type="capsule" fromto="0 -0.02 0 0 0.02 0"/>
										<joint name="r_wrist_flex_joint" type="hinge" pos="0 0 0" damping=".1" range="-1.094 0" axis="0 1 0"/>
										<body name="r_wrist_roll_link" pos="0 0 0">
											<joint limited="true" name="r_wrist_roll_joint" type="hinge" pos="0 0 0" damping="0.1" range="-1.5 1.5" axis="1 0 0"/>
											<body name="tips_arm" pos="0 0 0">
												<geom name="tip_arml" size="0.01" type="sphere" pos="0.1 -0.1 0."/>
												<geom name="tip_armr" size="0.01" type="sphere" pos="0.1 0.1 0."/>
											</body>
											<geom contype="1" conaffinity="1" size="0.02" type="capsule" fromto="0 -0.1 0. 0.0 +0.1 0"/>
											<geom contype="1" conaffinity="1" size="0.02" type="capsule" fromto="0 -0.1 0. 0.1 -0.1 0"/>
											<geom contype="1" conaffinity="1" size="0.02" type="capsule" fromto="0 +0.1 0. 0.1 +0.1 0"/>
										</body>
									</body>
								</body>
							</body>
						</body>
					</body>
				</body>
			</body>
		</body>
		<body name="object" pos="-9.98622258027 -10.9207541057 -0.25276001745">
			<geom contype="1" rgba="1 1 1 1" type="mesh" mesh="object_mesh" conaffinity="0" density="173.329920017"/>
			<joint name="obj_slidey" type="slide" pos="0 0 0" damping="2.6071486770386283" range="-10.3213 10.3" axis="0 1 0"/>
			<joint name="obj_slidex" type="slide" pos="0 0 0" damping="2.6071486770386283" range="-10.3213 10.3" axis="1 0 0"/>
		</body>
		<body name="goal" pos="0.45 -0.05 -0.323">
			<geom contype="0" rgba="1 0 0 1" size="0.08 0.001 0.1" type="cylinder" conaffinity="0" density="0.00001"/>
			<joint name="goal_slidey" type="slide" pos="0 0 0" damping="0.5" range="-10.3213 10.3" axis="0 1 0"/>
			<joint name="goal_slidex" type="slide" pos="0 0 0" damping="0.5" range="-10.3213 10.3" axis="1 0 0"/>
		</body>
	</worldbody>
	<asset >
		<mesh file="/root/code/rllab/vendor/mujoco_models/Vase_Mode.stl" name="object_mesh" scale="0.00207406980282 0.00207406980282 0.00207406980282"/>
	</asset>
	<actuator >
		<motor joint="r_shoulder_pan_joint" ctrlrange="-2.0 2.0" ctrllimited="true"/>
		<motor joint="r_shoulder_lift_joint" ctrlrange="-2.0 2.0" ctrllimited="true"/>
		<motor joint="r_upper_arm_roll_joint" ctrlrange="-2.0 2.0" ctrllimited="true"/>
		<motor joint="r_elbow_flex_joint" ctrlrange="-2.0 2.0" ctrllimited="true"/>
		<motor joint="r_forearm_roll_joint" ctrlrange="-2.0 2.0" ctrllimited="true"/>
		<motor joint="r_wrist_flex_joint" ctrlrange="-2.0 2.0" ctrllimited="true"/>
		<motor joint="r_wrist_roll_joint" ctrlrange="-2.0 2.0" ctrllimited="true"/>
	</actuator>
</mujoco>
